Workbook

Sheet 主要公式
A1: 速度计算条件
A2: 电机步距角(度) | C2: 1.8
A3: 细分 | C3: 256
A4: MRES | C4: =_xlfn.SWITCH(C3,256,0,128,1,64,2,32,3,16,4,8,5,4,6,2,7,1,8) -> 0
A5: 电机转一圈的微步数Count | C5: =360/C2*C3 -> 51200
A6: 时钟频率(Hz) | C6: 16000000
A7: a/AMAX= | C7: =(C6^2)/(512*256)/(2^24)/$C$5 -> 0.0022737368 | D7: 注：这是转换倍数
A8: AMAX/a= | C8: =1/C7 -> 439.80465 | D8: 注：这是转换倍数
A10: 实际转速(rpm)和速度相关寄存器(VSTART、V1、VMAX、VSTOP)之间的换算，以VMAX举例
A11: V(RPM)： | B11: 342 | C11: VMAX： | D11: =B11/60/$C$6*(2^24)*$C$5 -> 306016.42 | E11: 对应转速(RPS)： | F11: =B11/60 -> 5.7 | G11: 对应相同细分时步进频率(Hz) | I11: =B11/60*C5 -> 291840 | J11: 对应整步时步进频率(Hz) | L11: =I11/C3 -> 1140
A12: VMAX： | B12: 1678 | C12: V(RPM)： | D12: =B12*$C$6/(2^24)/$C$5*60 -> 1.8753111 | E12: 对应转速(RPS)： | F12: =D12/60 -> 0.031255186 | G12: 对应相同细分时步进频率(Hz) | I12: =D12/60*C5 -> 1600.2655 | J12: 对应整步时步进频率(Hz) | L12: =I12/C3 -> 6.2510371
A14: 实际加速度a和加减速相关寄存器(A1、AMAX、DMAX、D1)之间的换算，以AMAX举例
A15: A(RPS/S)： | B15: 0.0033489798 | C15: AMAX： | D15: =B15*$C$5*(2^41)/($C$6^2) -> 1.4728969
A16: AMAX： | B16: 30000 | C16: A(RPS/S)： | D16: =B16*($C$6^2)/(2^41)/$C$5 -> 68.212103 | E16: 加速过程的时间 | F16: =F11/D16 -> 0.083562884
A18: 速度阈值(rpm)，和速度阈值相关寄存器(TSTEP、TPWMTHRS、TCOOLTHRS、THIGH)之间的换算公式其实是一样的，下面以TPWMTHRS寄存器举例
A19: 设定堵转速度阈值(rpm) | B19: 261 | C19: 堵转速度阈值(ppt) | D19: =B19/60*$C$5*(2^24)/$C$6 -> 233538.85 | E19: TPWMTHRS(0x13) | F19: =MIN((2^20-1),2^24/$D$19*C3/256) -> 71.83908
A20: TPWMTHRS(0x13) | B20: 261 | C20: 堵转速度阈值(ppt) | D20: =(2^24)/B20/256*$C$3 -> 64280.521 | E20: V(RPM)： | F20: =D20*$C$6/(2^24)/$C$5*60 -> 71.83908
A21: 注： 1、黄色单元格是数据输入框，里面没有公式。 2、细分在可芯片的CHOPCONF寄存器的MRES参数设置。如果MRES参数为0，是256细分；如果1，是128细分，如果2，是64细分，依次递减；如果值为8，电机整步运行。 3、TMC5系列芯片都有个CLK引脚，如果此引脚接GND，则使用内部时钟。 TMC5160内部时钟频率典型值 12MHz； TMC5240、TMC5272芯片的内部时钟频率 12.5MHz； TMC5130、TMC5041、TMC5072芯片内部时钟频率 13.2MHz； 如果用评估板套件测试，时钟频率都是 16MHz。 4、如果需要接外部时钟，把外部时钟源提供给CLK引脚。可有有源晶振提供，或由MCU提供。 5、时钟频率会影响电机转速，例如VMAX寄存器配置一样，时钟频率不一样，电机实际转速会不一样。
A25: 下面是具体公式
A26: 1、末速度ωt、初速度ω0、时间和行程S之间的关系
A29: 2、加速度a、末速度ωt、初速度ω0、时间t之间的关系
A32: 3、实际转速ω(rps)和速度相关寄存器(VSTART、V1、VMAX、VSTOP)之间的换算，以VMAX举例
A36: 4、实际加速度a和加减速相关寄存器(A1、AMAX、DMAX、D1)之间的换算，以AMAX举例

Sheet 6点斜坡举例
A18: 电机步距角 | C18: =主要公式!C2 -> 1.8
A19: 细分 | C19: =主要公式!C3 -> 256
A20: MRES | C20: =主要公式!C4 -> 0
A21: 一圈需要的微步数Count | C21: =360/C18*C19 -> 51200
A22: 时钟频率(Hz) | C22: =主要公式!C6 -> 16000000
A23: 注：上面可以不修改，会同步《主要公式》工作簿里的 C2:C6 单元格内容
A26: 行程S | B26: (ustep) | C26: 圈数 | D26: 时间(sec)
A27: 加速1阶段 | B27: 1000 | C27: =B27/$C$21 -> 0.01953125 | D27: 0.1
A28: 加速2阶段 | B28: 3996 | C28: =B28/$C$21 -> 0.078046875 | D28: 0.15
A29: 匀速阶段 | B29: 51200 | C29: =B29/$C$21 -> 1 | D29: =F71 -> 1.5384615
A30: 减速1阶段 | B30: =F80 -> 6127.2 | C30: =B30/C21 -> 0.11967187 | D30: 0.23
A31: 减速2阶段 | B31: =F93 -> 4101.955 | C31: =B31/C21 -> 0.080116309 | D31: 0.41
A33: 小计 | B33: =SUM(B27:B31) -> 66425.155 | D33: =SUM(D27:D31) -> 2.4284615
A35: 加速1阶段 | B35: 已知第1段的行程，时间，VSTART=0，求A1和V1
B36: 根据公式：
B38: 算出 | C38: 实际加速度aA1(rotations/(s^2)) | F38: =(C27*2)/(D27^2) -> 3.90625
B39: 根据公式：
B41: 算出 | C41: 寄存器A1(ppt2) | F41: =F38/($C$22^2)*(2^41)*C21 -> 1717.9869 | G41: 取整 | H41: =F41 -> 1717.9869
B42: 根据公式：
B44: 算出 | C44: 实际转速VV1(rps) | F44: =F38*D27 -> 0.390625
B45: 根据公式：
B47: 算出 | C47: 寄存器V1(ppt) | F47: =F44*C21*(2^24)/$C$22 -> 20971.52 | G47: 取整 | H47: =F47 -> 20971.52
B48: 也可根据公式：
B50: 算出 | C50: 寄存器V1(ppt) | F50: =(B27*F41*256)^0.5 -> 20971.52 | G50: 取整 | H50: =F50 -> 20971.52
A53: 加速2阶段 | B53: 已知第2段的行程、时间、V1，求AMAX和VMAX
B54: 根据公式：
B56: 算出 | C56: 实际加速度aAMAX(rotations/(s^2)) | F56: =(C28-F44*D28)*2/(D28^2) -> 1.7291667
B57: 根据公式：
B59: 算出 | C59: 寄存器AMAX(ppt2) | F59: =F56/($C$22^2)*(2^41)*C21 -> 760.49554 | G59: 取整 | H59: =F59 -> 760.49554
B60: 根据公式：
B62: 算出 | C62: 实际转速VVMAX(rps) | F62: =F44+F56*D28 -> 0.65
B63: 根据公式：
B65: 算出 | C65: 寄存器VMAX(ppt) | F65: =F62*C21*(2^24)/$C$22 -> 34896.609 | G65: 取整 | H65: =F65 -> 34896.609
A68: 匀速阶段 | B68: 第3段是匀速运动。根据行程求出时间，或根据时间求出行程
B69: 根据公式：
B71: 算出 | C71: 需要时间t(sec) | F71: =C29/F62 -> 1.5384615
A74: 减速1阶段 | B74: 第4段的VMAX、V1、行程和时间已经确定，根据公式求出减速度aDMAX，再求出寄存器DMAX，也会影响行程
B75: 根据公式：
B77: 算出 | C77: 实际减速度aDMAX(rotations/(s^2)) | F77: =(F44-F62)/D30 -> -1.1277174
C78: 寄存器DMAX(ppt2) | F78: =-F77/($C$22^2)*(2^41)*C21 -> 495.97535 | G78: 取整 | H78: =F78 -> 495.97535
...

Sheet T型斜坡计算
A1: 说明： 1、这表是用于计算梯型加减速运动轨迹。 2、可从黄色背景单元格的输入参数，这种单元格没有公式。 3、推导公式依据加速度计算公式，这是初中物理的知识。 4、用这表格，可先确认好三个运动阶段的需要行程和时间，去计算目标位置（相对位移）、AMAX寄存器、VMAX寄存器、DMAX寄存器的值。这表格也支持修改VSTART寄存器和VSTOP寄存器。 5、其中匀速运动阶段，只能根据时间计算位移，或者根据位移计算时间。 6、TMC5240的内部时钟典型值是12.5MHz。芯片的时钟频率会影响速度、加速度计算。
A3: 表1、填入基本参数
A4: 电机步距角(°) | C4: =主要公式!C2 -> 1.8
A5: 细分 | C5: =主要公式!C3 -> 256
A6: MRES | C6: =主要公式!C4 -> 0
A7: 一圈需要的微步数Count | C7: =主要公式!C5 -> 51200
A8: 时钟频率(Hz) | C8: =主要公式!C6 -> 16000000
A9: 注：上面可以不修改，会同步《主要公式》工作簿里的 C2:C6 单元格内容
A11: 表2、填入每段运动需要的行程和花费时间
B12: 行程(微步数) | C12: 对应的圈数 | D12: 花费时间(S)
A13: 加速阶段 | B13: 4000 | C13: =B13/$C$7 -> 0.078125 | D13: 0.05
A14: 匀速阶段 | B14: 591680 | C14: =B14/$C$7 -> 11.55625 | D14: 2 | E14: 提示：根据我的计算步骤，匀速阶段只能根据行程求时间，或者根据时间求出行程
A15: 减速阶段 | B15: 4000 | C15: =B15/$C$7 -> 0.078125 | D15: 0.1
A16: 小计： | B16: =SUM(B13:B15) -> 599680 | C16: =SUM(C13:C15) -> 11.7125 | D16: =SUM(D13:D15) -> 2.15
A18: VSTART(0x23)寄存器的值 | C18: 0 | D18: 对应转速（rps） | E18: =C18*$C$8/(2^24)/$C$7 -> 0
A19: VSTOP(0x2B)寄存器的值 | C19: 10 | D19: 对应转速（rps） | E19: =C19*$C$8/(2^24)/$C$7 -> 0.00018626451 | F19: 注意：VSTOP寄存器的值不建议设置为0，至少要是10
A22: 表3、根据表1、表2的参数推导AMAX、VMAX、DMAX寄存器的值
A23: 加速阶段 | B23: 已知加速阶段的行程所对应的圈数，花费时间，VSTART，可确定加速度和最大速度
B24: 根据公式：
B26: 可确认 | C26: 加速度a(rps/s) | E26: =(2*(C13-E18*D13))/(D13^2) -> 62.5 | F26: 对应的AMAX寄存器的值，并取整 | H26: =E26/($C$8^2)*(2^41)*C7 -> 27487.791
B27: 根据公式：
B29: 可确认 | C29: 最大转速(rps) | E29: =E18+E26*$D$13 -> 3.125 | F29: 对应的VMAX寄存器的值，并取整 | H29: =E29*$C$7*(2^24)/$C$8 -> 167772.16
A32: 匀速阶段 | B32: 匀速运动阶段，已知最大速度，可根据行程求出时间，或根据时间求出行程
B33: 根据公式：
B35: 可确认 | C35: 根据位移计算需要时间t(s) | E35: =C14/E29 -> 3.698
B36: 或者确认 | C36: 根据花费时间计算转动圈数 | E36: =E29*D14 -> 6.25 | F36: 这里圈数对应的位置数 | H36: =E36*C8 -> 1e+08
A39: 减速阶段 | B39: 最后确认减速阶段过程。上面已经确认好最大速度，停止速度，花费时间，和行程S，可确认减速阶段的DMAX寄存器
B40: 根据公式：
B42: 可确认 | C42: 减速度a(rps/s) | E42: =(E29^2-E19^2)/(2*C15) -> 62.5 | F42: 对应的DMAX寄存器的值，并取整 | H42: =E42/($C$8^2)*(2^41)*C7 -> 27487.791
